begin
Traceback (most recent call last):
  File "/public/home/imgbreaker/Desktop/CISFDA/CISFDA/main_test.py", line 149, in <module>
    contrastive_label = torch.tensor([0]).cuda()
                        ^^^^^^^^^^^^^^^^^^^^^^^^
RuntimeError: CUDA error: out of memory
CUDA kernel errors might be asynchronously reported at some other API call, so the stacktrace below might be incorrect.
For debugging consider passing CUDA_LAUNCH_BLOCKING=1.
Compile with `TORCH_USE_CUDA_DSA` to enable device-side assertions.

ERROR conda.cli.main_run:execute(124): `conda run python -u /public/home/imgbreaker/Desktop/CISFDA/CISFDA/main_test.py --source_model /public/home/imgbreaker/CIUDA/ProCA-main/ProCA-main/model_source/office_home/20240414-0211-OH_RealWorld_ce_singe_gpu_resnet50_best_param.pth --weight_model /public/home/imgbreaker/CIUDA/ProCA-main/ProCA-main/model_source/office_home/negative/20240416-2141-OH_RealWorld_ce_singe_gpu_resnet50_best_neg_param.pth --source RealWorld --target Art --model_name final_officehome --txt World2Art.txt --dataset office-home/Art --num_class 65` failed. (See above for error)
begin
Traceback (most recent call last):
  File "/public/home/imgbreaker/Desktop/CISFDA/CISFDA/main_test.py", line 159, in <module>
    pretrained_net.load_state_dict(torch.load(args.source_model))
                                   ^^^^^^^^^^^^^^^^^^^^^^^^^^^^^
  File "/public/home/imgbreaker/anaconda3/envs/CIUDA/lib/python3.11/site-packages/torch/serialization.py", line 998, in load
    with _open_file_like(f, 'rb') as opened_file:
         ^^^^^^^^^^^^^^^^^^^^^^^^
  File "/public/home/imgbreaker/anaconda3/envs/CIUDA/lib/python3.11/site-packages/torch/serialization.py", line 445, in _open_file_like
    return _open_file(name_or_buffer, mode)
           ^^^^^^^^^^^^^^^^^^^^^^^^^^^^^^^^
  File "/public/home/imgbreaker/anaconda3/envs/CIUDA/lib/python3.11/site-packages/torch/serialization.py", line 426, in __init__
    super().__init__(open(name, mode))
                     ^^^^^^^^^^^^^^^^
FileNotFoundError: [Errno 2] No such file or directory: '/public/home/imgbreaker/CIUDA/ProCA-main/ProCA-main/model_source/office_home/20240414-0211-OH_RealWorld_ce_singe_gpu_resnet50_best_param.pth'
ERROR conda.cli.main_run:execute(124): `conda run python -u /public/home/imgbreaker/Desktop/CISFDA/CISFDA/main_test.py --source_model /public/home/imgbreaker/CIUDA/ProCA-main/ProCA-main/model_source/office_home/20240414-0211-OH_RealWorld_ce_singe_gpu_resnet50_best_param.pth --weight_model /public/home/imgbreaker/CIUDA/ProCA-main/ProCA-main/model_source/office_home/negative/20240416-2141-OH_RealWorld_ce_singe_gpu_resnet50_best_neg_param.pth --source RealWorld --target Art --model_name final_officehome --txt World2Art.txt --dataset office-home/Art --num_class 65` failed. (See above for error)
